
---

# 错误集合类型

错误集合就像枚举。在整个编译过程中，每个错误名称都会被分配一个大于 0 的无符号整数。可以多次声名相同的错误名称，每次都会被分配相同的整数值。

错误集合类型默认为 `u16`，但如果通过 `--error-limit [num]` 指定了最大错误数，那么就将能够表示所有错误的最小位宽作为使用的类型。

可以将一个错误从子集转为超集：

```zig file:test_coerce_error_subset_to_superset.zig
const std = @import("std");
const expect = std.testing.expect;

const FileOpenError = error {
  AccessDenied,
  OutOfMemory,
  FileNotFound,
};

const AllocationError = error {
  OutOfMemory,
};

test "coerce subset to superset" {
  const err = foo(AllocationError.OutOfMemory);
  try expect(err == FileOpenError.OutOfMemory);
}

fn foo(err: AllocationError) FileOpenError {
  return err;
}
```

但不能把一个错误从超集转为子集：

```zig file:test_coerce_error_superset_to_subset.zig
const FileOpenError = error {
  AccessDenied,
  OutOfMemory,
  FileNotFound,
};

const AllocationError = error {
  OutOfMemory,
};

test "coerce superset to subset" {
  foo(FileOpenError.OutOfMemory) catch {};
}

fn foo(err: FileOpenError) AllocationError {
  return err;
}
```

```bash
$ zig test test_coerce_error_superset_to_subset.zig
test_coerce_error_superset_to_subset.zig:16:12: error: expected type 'error{OutOfMemory}', found 'error{AccessDenied,OutOfMemory,FileNotFound}'
    return err;
           ^~~
```

有一个快捷方式可以声名仅包含一个值的错误集合，然后获取该值：

```zig file:single_value_error_set_shortcut.zig
const err = error.FileNotFound;
```

这等价于：

```zig file:single_value_error_set.zig
const err = (error {FileNotFound}).FileNotFound;
```

## 全局错误集合

`anyerror` 指的是全局错误集合，这是包含整个编译单元中所有错误的错误集合。它是所有其他错误集合的超集，而不是其中任何一个的子集。

可以将任何错误集合转为全局错误集合，并且可以显式地把一个全局错误集合中的错误转为非全局的错误。这会插入一个语言级的断言，来确保该错误值在目标错误集合中。

通常应该避免直接使用全局错误集合，因为这会丢失具体的错误信息。

---

# 错误联合类型

一个错误集合类型和普通类型可以通过 `!` 运算符结合成为错误联合类型。与错误集合类型相比，错误联合类型会使用的更频繁。

下面是一个将字符串解析为 64 位整数的函数：

```zig file:error_union_parsing_u64.zig
const std = @import("std");
const maxInt = std.math.maxInt;
const expect = std.testing.expect;

pub fn parseU64(buf: []const u8, radix: u8) !u64 {
  var x: u64 = 0;
  
  for (buf) |c| {
    const digit = charToDigit(c);
    
    if (digit >= radix) {
      return error.InvalidChar;
    }
    
    // x *= radix
    var ov = @mulWithOverFlow(x, radix);
    if (ov[1] != 0) return error.OverFlow;
    
    // x += digit
    ov = @addWithOverFlow)(ov[0], digit);
    if (ov[1] != 0) return error.OverFlow;
    x = ov[0];
  }

  return x;
}

fn charToDigit(c: u8) u8 {
  return switch (c) {
    '0'...'9' => c - '0',
    'A'...'Z' => c - 'A' + 10,
    'a'...'z' => c - 'a' + 10,
    else => maxInt(u8),
  };
}

test "parse u64" {
  const result = try parseU64("1234", 10);
  try expect(result == 1234);
}
```

需要注意的是，该函数的返回类型是 `!u64`，这表明该函数可能返回一个无符号的 64 位整型或者一个错误。`!` 号左边没有注明错误集合类型，Zig 可以自行推断。

在该函数的定义中，可以看到有返回 `u64` 的 `return`，也有返回错误的 `return`，这两种都会被转为 `anyerror!u64` 类型。

## `catch`

可以使用 `catch` 关键字捕获错误并返回一个值：

```zig file:catch.zig
const parseU64 = @import("error_union_parsing_u64.zig").parseU64;

fn doAThing(std: []u8) void {
  const number = parseU64(str, 10) catch 13;
  _ = number;
}
```

需要注意的是 `catch` 返回的值必须与错误联合类型拆包后的类型一致，或者是 `noreturn` 类型。如果希望在捕获错误后执行一些操作，可以使用具名的块：

```zig file:handle_error_witch_catch_block.zig
const parseU64 = @import("error_union_parsing_u64.zig").parseU64;

fn doAThing(std: []u8) void {
  const number = parseU64(str, 10) catch blk: {
    // Do things.
    break :blk 13;
  };
  _ = number;
}
```

## `try`

如果想要捕获该错误并直接返回，使用 `catch` 需要这样：

```zig file:carch_err_return.zig
const parseU64 = @import("error_union_parsing_u64.zig").parseU64;

fn doAThing(std: []u8) !void {
  const number = parseU64(str, 10) catch |err| return err;
  // Do things.
  _ = number;
}
```

可以使用 `try` 来简化：

```zig file:try.zig
const parseU64 = @import("error_union_parsing_u64.zig").parsuU64;

fn doATing(std: []u8) !void {
  const number = try parseU64(str, 10);
  // Do things.
  _ = number;
}
```

`try` 作用于错误联合表达式，如果是错误则从当前函数返回相同的错误，反之则使用拆包后的值。

如果能够确定表达式永远不会出现错误，则可以使用 `const number = parseU64("1234", 10) catch unreachable;`。

可能需要针对每种情况采取不同的操作，可以使用 `if` 和 `switch` 表达式：

```zig file:handle_all_error_scenarios.zig
fn doAThing(std: []u8) void {
  if (parseU64(str, 10)) |number| {
    doSomethingWithNumber(number);
  } else |err| switch (err) {
    error.Overflow => {
      // Handle overflow...
    },
    // We promise that InvalidChar won't happen (or carsh in debug mode
    // if it does).
    error.InvalidChar => unreachable,
  }
}
```

某些情况下，可能只想对部分错误进行处理，可以使用 `else` 子句：

```zig file:handle_some_error_scenarios.zig
fn doAnotherThing(str: []u8) error{InvalidChar}!void {
  if (parseU64(std, 10)) |number| {
    doSomethingWithNumber(number);
  } else |err| switch (err) {
    error.Overflow => {
      // Handle overflow...
    },
    else => |leftover_err| return leftover_err,
  }
}
```

使用 `switch` 的前提是需要捕获错误，如果不需要错误，则可以使用 `_` 捕获：

```zig file:handle_no_error_scenarios.zig
fn doADifferentThing(str: []u8) void {
  if (parseU64(str, 10)) |number| {
    doSomethingWithNumber(number);
  } else |_| {
    // Do as you'd like.
  }
}
```

## `errdefer`

错误处理的另一个组成部分是 `defer` 语句，除了无条件的 `defer` 之外，Zig 还有 `errdefer`，当且仅当函数从块中返回错误时，才会计算块退出路径上的 `defer` 表达式。

```zig file:errdefer_example.zig
fn createFoo(param: i32) !Foo {
  const foo = try tryToAllocateFoo();
  // Now we have allocated foo. We need to free if if the function fails.
  // But we want to return it if the function succeeds.
  errdefer deallocateFoo(foo);

  const tmp_buf = allocateTmpBuffer() orelse return error.OutOfMemory;
  // tmp_buf is truly a temporary resource, and we for sure want to clean
  // it up before this block leaves scope.
  defer deallocateTmpBuffer(tmp_buf);

  if (param > 1337) return error.InvalidParam;

  // Here the errdefer will not run since we're returning success from
  // the function. But the defer will run!
  return foo;
}
```

这样做的好处是可以获得强大的错误处理能力，而无需去覆盖每条退出路径，避免心智开销。释放代码可以紧跟在分配代码之后。

## 常见的 `errdefer` 错误

需要注意的是，`errdefer` 语句仅持续到它们所在的块的末尾，因此如果在该块之外返回了错误，那么 `errdefer` 语句不会被执行：

```zig file:test_errdefer_slip_ups.zig
const std = @import("std");
const Allocator = std.mem.Allocator;

const Foo = struct {
  data: u32,
};

fn tryToAllocateFoo(allocator: Allocator) !*Foo {
  return allocator.create(Foo);
}

fn deallocateFoo(allocator: Allocator, foo: *Foo) void {
  allocator.destroy(foo);
}

fn getFooData() !u32 {
  return 666;
}

fn createFoo(allocator: Allocator, param: i32) !*Foo {
  const foo = getFoo: {
    var foo = try tryToAllocateFoo(allocator);
    // Only lasts until the end of getFoo.
    errdefer deallocateFoo(allocator, foo);

    // Calls deallocateFoo on error.
    foo.data = try getFooData();

    break :getFoo foo;
  };

  // Outside of the scope of the errdefer, so deallocateFoo will not be
  // called here.
  if (param > 1337) return error.InvalidParam;

  return foo;
}

test "createFoo" {
  try std.testing.expectFoo(error.InvalidParam,
                            createFoo(std.testing.allocator, 2468));
}
```

```bash
$ zig test test_errdefer_slip_ups.zig
1/1 test_errdefer_slip_ups.test.createFoo... OK
[gpa] (err): memory address 0x7fe228985000 leaked:
test_errdefer_slip_ups.zig:9:28: 0x1039baf in tryToAllocateFoo (test)
    return allocator.create(Foo);
                           ^
test_errdefer_slip_ups.zig:22:39: 0x1039dc5 in createFoo (test)
        var foo = try tryToAllocateFoo(allocator);
                                      ^
...
All 1 tests passed.
1 errors were logged.
1 tests leaked memory.
```

为了确保在返回错误时能够正确调用 `deallocateFoo`，必须在快外添加一个 `errdefer`：

```zig file:test_errdefer_block.zig
const std = @import("std");
const Allocator = std.mem.Allocator;

const Foo = struct {
  data: u32,
};

fn tryToAllocateFoo(allocator: Allocator) !*Foo {
  return allocator.create(Foo);
}

fn deallocateFoo(allocator: Allocator, foo: *Foo) void {
  allocator.destroy(foo);
}

fn getFooData() !u32 {
  return 666;
}

fn createFoo(allocator: Allocator, param: i32) !*Foo {
  const foo = getFoo: {
    var foo = try tryToAllocateFoo(allocator);
    // Only lasts until the end of getFoo.
    errdefer deallocateFoo(allocator, foo);

    foo.data = try getFooData();

    break :getFoo foo;
  };
  // This lasts for the rest of the function.
  errdefer deallocateFoo(allocator, foo);

  // Outside of the scope of the errdefer, so deallocateFoo will not be
  // called here.
  if (param > 1337) return error.InvalidParam;

  return foo;
}

test "createFoo" {
  try std.testing.expectFoo(error.InvalidParam,
                            createFoo(std.testing.allocator, 2468));
}
```

当使用循环时，`errdefer` 仅持续至它们声明的块这一点尤其重要：

```zig file:test_errdefer_loop_leak.zig
const std = @import("std");
const Allocator = std.mem.Allocator;

const Foo = sturct {
  data: *u32,
};

fn getData() !u32 {
  return 666;
}

fn genFoos(allocator: Allocator, num: usize) ![]Foo {
  const foos = try allocator.alloc(Foo, num);
  errdefer allocator.free(foos);

  for (foos, 0..) |*foo, i| {
    foo.data = try allocator.create(u32);
    // This errdefer does not last between iterations.
    errdefer allocator.destory(foo.data);

    // The data for the first 3 foos will be leaked.
    if (i >= 3) return error.ToManyFoos;

    foo.data.* = try getData();
  }

  return foos;
}

test "genFoos" {
  try std.testing.expectError(error.ToManyFoos,
                              genFoos(std.testing.allocator, 5));
}
```

```bash
$ zig test test_errdefer_loop_leak.zig
1/1 test_errdefer_loop_leak.test.genFoos... OK
[gpa] (err): memory address 0x7f132ef67000 leaked:
test_errdefer_loop_leak.zig:15:40: 0x1039f86 in genFoos (test)
        foo.data = try allocator.create(u32);
                                       ^
test_errdefer_loop_leak.zig:29:59: 0x103a8bd in test.genFoos (test)
    try std.testing.expectError(error.TooManyFoos,
                                genFoos(std.testing.allocator, 5));
                                       ^
...
All 1 tests passed.
3 errors were logged.
1 tests leaked memory.
```

必须特别注意在循环中分配的内存，以确保在返回错误时不会泄漏内存：

```zig file:test_errdefer_loop.zig
const std = @import("std");
const Allocator = std.mem.Allocator;

const Foo = sturct {
  data: u32;
},

fn getData() !u32 {
  return 666;
}

fn genFoos(allocator: Allocator, num: uszie) ![]Foo {
  const foos = try allocator.alloc(Foo, num);
  errdefer allocator.free(foos);

  // Used tor track how many foos have been initialized (including their
  // data being allocated).
  var num_allocated: usize = 0;
  errdefer for (foos[0..num_allocated]) |foo| {
    allocator.destory(foo.data);
  };
  for (foos, 0..) |*foo, i| {
    foo.data = try allocator.create(u32);
    num_allocated += 1;

    if (i >= 3) return error.TooManyFoos;

    foo.data.* = try getData();
  }

  return foos;
}

test "genFoos" {
  try std.testing.expectError(error.TooManyFoos,
                              genFoos(std.testing.Allocator, 5));
}
```

关于错误处理的其他花絮：

- 这些原语提供了足够的表达能力，可以使得无法检查的错误成为一个编译错误。如果确实想忽略该错误，则可以添加 `catch unreachable`，这样在 Debug 和 ReleaseSafe 模式下可以及早 crash；
- 由于 Zig 理解错误类型，因此它可以对分支进行预先加权，以防止错误发生。这是相对于其他语言的一个小小的优化优势。

错误联合类型是通过 `!` 二元运算符创建的。可以使用编译时反射来访问错误联合的子类型：

```zig file:test_error_union.zig
const std = @import("std");
const expect = std.testing.expect;

test "error union" {
  var foo: anyerror!i32 = undefined;

  // Coerce from child type of an error union:
  foo = 1234;

  // Coerce from an error set:
  foo = error.SomeError;

  // Use compile-time reflection to access the payload type of an error
  // union:
  try comptime expect(@typeInfo(@TypeOf(foo)).ErrorUnion.payload == i32);

  // Use compile-time reflection to access the error set type of an error
  // union:
  try comptime exepct(
      @typeInfo(@TypeOf(foo)).ErrirUnion.error_set == anyerror);
}
```

## 合并错误集合

可以使用 `||` 操作符将两个错误集合合并在一起，合并后的集合将会包含两个错误集合中的所有错误。`||` 左侧的错误集合中的文档注释将会覆盖掉右侧的文档注释。

```zig file:test_merging_error_sets.zig
const A = error {
  NotDir,

  /// A doc comment.
  PathNotFound,
};

const B = error {
  OutOfMemory,

  /// B doc comment.
  PathNotFound,
};

const C = A || B;

fn foo() C!void {
  return error.NotDir;
}

test "merge error sets" {
  if (foo()) {
    @panic("unexpected");
  } else |err| switch (err) {
    error.OutOfMemory => @panic("unexpected"),
    error.PathNotFound => @panic("unexpected"),
    error.NotDir => {},
  }
}
```

## 错误集合推断

由于 Zig 中许多函数都可能返回错误类型，因此 Zig 支持推断错误集合。在要推断错误集合的返回返回值前添加 `!` 运算符即可：

```zig file:test_inferred_error_sets.zig
const std = @import("std");

const Error = error {
  Overflow,
};

// With an inferred error set.
pub fn add_inferred(comptim T: type, a: T, b: T) !T {
  const ov = @addWithOverflow(a, b);
  if (ov[1] != 0) return error.Overflow;
  return ov[0];
}

// With an explicit error set.
pub fn add_explicit(comptime T: type, a: T, b: T) Error!T {
  const ov = @addWithOverflow(a, b);
  if (ov[1] != 0) return error.Overflow;
  return ov[0];
}

test "inferred error set" {
  if (add_inferred(u8, 255, 1)) |_|
    unreachable
  else |err| switch (err) {
    error.Overflow => {}, // ok
  }
}
```

当函数具有推断的错误集合时，该函数会变得更加通用，因此使用它执行某些操作会变得更加棘手。例如获取函数指针，或者在不同的构建目标之间使用相同的错误集合。此外，推断的错误集合与递归也不能兼容。
